Workbook

Sheet Tool Guidance
A1: Aperçu de l’outil ESDacademy « audit fonctionnel »
A3: Cette outils a pour but de qualifier son SMSI (Système de management en sécurité de l’information) à l’aide de la valorisation des différents contrôles demandés par les exigences de la norme 27001.
A4: Instruction d’utilisation
A5: Pre-évaluation
A6: 1. Déterminer le périmètre d’évaluation | C6: Travailler avec les acteurs concernés pour déterminer quelle est la portée appropriée de l'évaluation.
A7: 2. Collecter les preuves | C7: Identifiez et centralisez autant de preuves que possible. Cela peut inclure des documents stratégiques, des documents de processus, des relevés de notes d'entrevue, etc.
A8: 3. Préparer l’outil | C8: Utiliser le périmètre d’évaluation permet d’identifier ce qu’il ne pourrait pas être convenable dans le questionnaire. En outre, lorsque les questions d'audit suggérées ne sont pas pertinentes, elles peuvent être remplacées par celles qui conviennent.
A9: Évaluation
A10: 4. Examiner les zones de contrôle | C10: Examiner les preuves pour chaque contrôle et déterminer la conformité avec les exigences. Cette outil permet de faire cela avec des incréments de 5%.
A11: 5. Déterminer le niveau de conformité | C11: À la fin de l’évaluation, l’outil vous fournira un niveau global de conformité par zone de contrôle et par des contrôles individuels.
A12: Post évaluation
A13: 6. Enregistrement des zones faibles | C13: Enregistrer les zones, contrôles non convenable (normalement moins que 90%)
A14: 7. Créer un plan d’amélioration | C14: Pour chaque zone de faiblesse, travailler avec les personnes concernés par la zone pour déterminer comment le contrôle peut être amélioré.
A15: 8. Prévoir une ré-évaluation | C15: Organisez une date pour examiner les zones faibles pour définir une cible pour les plans d'amélioration.
A16: Cycle de vie de la revue
A17: 9. Prévoir le revue du SMSI | C17: Assurez-vous que le SMSI est réévalué régulièrement, idéalement tous les 12 mois.

Sheet Dashboard
A1: Audit fonctionnel (ISO27001:2013 SCORE)

Sheet Compliance per section
A1: Conformité par section
A2: Standard | B2: Section | C2: Status
A3: A.5 | B3: Politiques de sécurité de l’information | C3: =AVERAGE('Compliance Checklist'!F5:F6) -> 0
A4: A.6 | B4: Organisation de la sécurité de l’information | C4: =AVERAGE('Compliance Checklist'!F9:F13,'Compliance Checklist'!F15,'Compliance Checklist'!F16) -> 0
A5: A.7 | B5: La sécurité des ressources humaines | C5: =AVERAGE('Compliance Checklist'!F19,'Compliance Checklist'!F20,'Compliance Checklist'!F22,'Compliance Checklist'!F23,'Compliance Checklist'!F24,'Compliance Checklist'!F26) -> 0
A6: A.8 | B6: Gestion des actifs | C6: =AVERAGE('Compliance Checklist'!F29:F32,'Compliance Checklist'!F34:F36,'Compliance Checklist'!F38:F40) -> 0
A7: A.9 | B7: Contrôle d’accès | C7: =AVERAGE('Compliance Checklist'!F43:F44,'Compliance Checklist'!F46:F51,'Compliance Checklist'!F53,'Compliance Checklist'!F55:F59) -> 0
A8: A.10 | B8: Cryptographie | C8: =AVERAGE('Compliance Checklist'!F62:F63) -> 0
A9: A.11 | B9: Sécurité physique et environnementale | C9: =AVERAGE('Compliance Checklist'!F66:F71,'Compliance Checklist'!F73:F81) -> 0
A10: A.12 | B10: Sécurité liée à l’exploitation | C10: =AVERAGE('Compliance Checklist'!F84:F87,'Compliance Checklist'!F89,'Compliance Checklist'!F91,'Compliance Checklist'!F93:F96,'Compliance Checklist'!F98,'Compliance Checklist'!F100:F101,'Compliance Checklist'!F103) -> 0
A11: A.13 | B11: Sécurité des communications | C11: =AVERAGE('Compliance Checklist'!F106:F108,'Compliance Checklist'!F110:F113) -> 0
A12: A.14 | B12: Acquisition, développement et maintenance des systèmes d’information | C12: =AVERAGE('Compliance Checklist'!F116:F118,'Compliance Checklist'!F120:F124,'Compliance Checklist'!F126:F128,'Compliance Checklist'!F130) -> 0
A13: A.15 | B13: Relations avec les fournisseurs | C13: =AVERAGE('Compliance Checklist'!F133:F135,'Compliance Checklist'!F137:F138) -> 0
A14: A.16 | B14: Gestion des incidents liés à la sécurité de l’information | C14: =AVERAGE('Compliance Checklist'!F141:F147) -> 0
A15: A.17 | B15: Aspects de la sécurité de l’information dans la gestion de la continuité de l’activité | C15: =AVERAGE('Compliance Checklist'!F150:F152,'Compliance Checklist'!F154) -> 0
A16: A.18 | B16: Conformité | C16: =AVERAGE('Compliance Checklist'!F157:F161,'Compliance Checklist'!F163:F165) -> 0
A20: Conformité globale | C20: =AVERAGE(C3:C16) -> 0

Sheet Compliance per control
A1: Conformité par contrôle
A2: Standard | B2: Section | C2: Status
A3: A.5.1 | B3: Orientations de la direction en matière de sécurité de l’information | C3: =AVERAGE('Compliance Checklist'!F5:F6) -> 0
A4: A.6.1 | B4: Organisation interne | C4: =AVERAGE('Compliance Checklist'!F9:F13) -> 0
A5: A.6.2 | B5: Appareils mobiles et télétravail | C5: =AVERAGE('Compliance Checklist'!F15:F16) -> 0
A6: A.7.1 | B6: Avant l’embauche | C6: =AVERAGE('Compliance Checklist'!F19:F20) -> 0
A7: A.7.2 | B7: Pendant la durée du contrat | C7: =AVERAGE('Compliance Checklist'!F22:F24) -> 0
A8: A.7.3 | B8: Rupture, terme ou modification du contrat de travail | C8: =AVERAGE('Compliance Checklist'!F26) -> 0
A9: A.8.1 | B9: Responsabilités relatives aux actifs | C9: =AVERAGE('Compliance Checklist'!F29:F32) -> 0
A10: A.8.2 | B10: Classification de l’information | C10: =AVERAGE('Compliance Checklist'!F34:F36) -> 0
A11: A.8.3 | B11: Manipulation des supports | C11: =AVERAGE('Compliance Checklist'!F38:F40) -> 0
A12: A.9.1 | B12: Exigences métier en matière de contrôle d’accès | C12: =AVERAGE('Compliance Checklist'!F43:F44) -> 0
A13: A.9.2 | B13: Gestion de l’accès utilisateur | C13: =AVERAGE('Compliance Checklist'!F46:F51) -> 0
A14: A.9.3 | B14: Responsabilités des utilisateurs | C14: =AVERAGE('Compliance Checklist'!F53) -> 0
A15: A.9.4 | B15: Contrôle de l’accès au système et aux applications | C15: =AVERAGE('Compliance Checklist'!F55:F59) -> 0
A16: A.10.1 | B16: Mesures cryptographiques | C16: =AVERAGE('Compliance Checklist'!F62:F63) -> 0
A17: A.11.1 | B17: Zones sécurisées | C17: =AVERAGE('Compliance Checklist'!F66:F71) -> 0
A18: A.11.2 | B18: Matériels | C18: =AVERAGE('Compliance Checklist'!F73:F81) -> 0
A19: A.12.1 | B19: Procédures et responsabilités liées à l’exploitation | C19: =AVERAGE('Compliance Checklist'!F84:F87) -> 0
A20: A.12.2 | B20: Protection contre les logiciels malveillants | C20: =AVERAGE('Compliance Checklist'!F89) -> 0
A21: A.12.3 | B21: Sauvegarde | C21: =AVERAGE('Compliance Checklist'!F91) -> 0
A22: A.12.4 | B22: Journalisation et surveillance | C22: =AVERAGE('Compliance Checklist'!F93:F96) -> 0
A23: A.12.5 | B23: Maîtrise des logiciels en exploitation | C23: ='Compliance Checklist'!F98 -> 0
A24: A.12.6 | B24: Gestion des vulnérabilités techniques | C24: =AVERAGE('Compliance Checklist'!F100:F101) -> 0
A25: A.12.7 | B25: Considérations sur l’audit du système d’information | C25: =AVERAGE('Compliance Checklist'!F103) -> 0
A26: A.13.1 | B26: Management de la sécurité des réseaux | C26: =AVERAGE('Compliance Checklist'!F106:F108) -> 0
A27: A.13.2 | B27: Transfert de l’information | C27: =AVERAGE('Compliance Checklist'!F110:F113) -> 0
A28: A.14.1 | B28: Exigences de sécurité applicables aux systèmes d’information | C28: =AVERAGE('Compliance Checklist'!F116:F118) -> 0
A29: A.14.2 | B29: Sécurité des processus de développement et d’assistance technique | C29: =AVERAGE('Compliance Checklist'!F120:F128) -> 0
A30: A.14.3 | B30: Données de test | C30: =AVERAGE('Compliance Checklist'!F130) -> 0
A31: A.15.1 | B31: Sécurité de l’information dans les relations avec les fournisseurs | C31: =AVERAGE('Compliance Checklist'!F133:F135) -> 0
A32: A.15.2 | B32: Gestion de la prestation du service | C32: =AVERAGE('Compliance Checklist'!F137:F138) -> 0
A33: A.16.1 | B33: Gestion des incidents liés à la sécurité de l’information et améliorations | C33: =AVERAGE('Compliance Checklist'!F141:F147) -> 0
A34: A.17.1 | B34: Continuité de la sécurité de l’information | C34: =AVERAGE('Compliance Checklist'!F150:F152) -> 0
A35: A.17.2 | B35: Redondances | C35: =AVERAGE('Compliance Checklist'!F154) -> 0
A36: A.18.1 | B36: Conformité aux obligations légales et réglementaires | C36: =AVERAGE('Compliance Checklist'!F157:F161) -> 0
A37: A.18.2 | B37: Revue de la sécurité de l’information | C37: =AVERAGE('Compliance Checklist'!F163:F165) -> 0

Sheet Compliance Checklist
A1: Référence | C1: Évaluation de la zone de conformité | E1: Résultat
A2: Checklist | B2: Standard | C2: Section | D2: Points d'évaluation initiaux | E2: Résultats | F2: Status
B3: A.5 | C3: Politiques de sécurité de l’information
B4: A.5.1 | C4: Orientations de la direction en matière de sécurité de l’information
A5: [ ] | B5: A.5.1.1 | C5: Politiques de sécurité de l'information | D5: 1. Existe-t-il des politiques de sécurité ? 2. Ces politiques sont-ils approuvées par le management ? 3. Ces politiques sont-elles communiqués aux employés de la société ? | F5: 0
A6: [ ] | B6: A.5.1.2 | C6: Revue des politiques de sécurité de l’information | D6: 1. Les politiques de sécurité sont-elles passées en revue ? 2. Les revues sont-elles à un intervalle régulier ? 3. Des revues sont-elles établissent lors de changements ? | F6: 0
B7: A.6 | C7: Organisation de la sécurité de l’information
B8: A.6.1 | C8: Organisation interne
A9: [ ] | B9: A.6.1.1 | C9: Fonctions et responsabilités liées à la sécurité de l’information | D9: Les responsabilités pour la protection des biens individuels et des processus de sécurité spécifiques sont-ils clairement identifiés, définis et communiqués aux parties concernés ? | F9: 0
A10: [ ] | B10: A.6.1.2 | C10: Séparation des tâches | D10: Les fonctions et les domaines de responsabilité sont-ils séparés, afin de limiter les possibilités de modification ou de mauvais usage, non autorisé(e) ou involontaire, des actifs de l’organisation ? | F10: 0
A11: [ ] | B11: A.6.1.3 | C11: Relation avec les autorités | D11: 1. Existe-t-il une procédure permettant de documenter quand, et par qui, des contacts avec les autorités compétentes (application de la loi, etc.) seront-ils effectués? 2. Existe-t-il un processus qui détaille comment et quand le contact est requis? 3. Existe-t-il un processus de partage systématique des contacts et des renseignements? | F11: 0
A12: [ ] | B12: A.6.1.4 | C12: Relation avec des groupes de travail spécialisés | D12: Des personnes dans l'organisation investies dans la sécurité du SI ont-elles des relations appropriées avec des groupes d’intérêt, des forums spécialisés, professionnels, associations dans la sécurité de l’information | F12: 0
A13: [ ] | B13: A.6.1.5 | C13: La sécurité de l’information dans la gestion de projet | D13: Tous les projets font-ils l'objet d'une évaluation de la sécurité de l'information? | F13: 0
B14: A.6.2 | C14: Appareils mobiles et télétravail
A15: [ ] | B15: A.6.2.1 | C15: Politique en matière d’appareils mobiles | D15: 1. Existe-t-il une politique de sécurité mobile ? 2. La politique est-elle approuvée par la direction? 3. Cette politique (document) reporte-t-il les risques additionnels concernant l’usage des appareils mobiles (Vol, utilisation de Hotspot, etc.) ? | F15: 0
A16: [ ] | B16: A.6.2.2 | C16: Télétravail | D16: 1. Y a-t-il une politique pour le télétravail ? 2. La politique est-elle approuvée par la direction? 3. Existe-t-il un processus défini pour que les « télétravailleurs » puissent accéder à distance à l’organisation ? 4. Les télétravailleurs ont-ils les conseils et l'équipement nécessaires pour protéger leurs biens? | F16: 0
B17: A.7 | C17: La sécurité des ressources humaines
B18: A.7.1 | C18: Avant l’embauche
A19: [ ] | B19: A.7.1.1 | C19: Sélection des candidats | D19: 1. La vérification des antécédents sont-elles effectuées sur tous les nouveaux candidats à l'emploi? 2. Ces contrôles sont-ils approuvés par l'autorité de gestion appropriée? 3. Les contrôles des antécédents sont-ils règlementaires, éthiques et pertinents ? 4. Le niveau de contrôle est-il en adéquation avec l’analyse de risque ? | F19: 0
A20: [ ] | B20: A.7.1.2 | C20: Termes et conditions d’embauche | D20: 1. Tous les employés, les parties prenantes et les utilisateurs tiers sont-ils priés de signer des accords de confidentialité et de non-divulgation? 2. Les contrats d'emploi / de services couvrent-ils spécifiquement la nécessité de protéger les informations commerciales? | F20: 0
B21: A.7.2 | C21: Pendant la durée du contrat
A22: [ ] | B22: A.7.2.1 | C22: Responsabilités de la direction | D22: 1. Les managers (de tous les niveaux) sont-ils engagés dans l’utilisation de la sécurité dans l’entreprise ? 2. Le management et la conduite des politiques conduit-il, encourage t-il les employés, les parties prenantes, les utilisateurs à appliquer les politiques et procédures de sécurité ? | F22: 0
A23: [ ] | B23: A.7.2.2 | C23: Sensibilisation, apprentissage et formation à la sécurité de l’information | D23: Les employés, parties prenantes sont-ils inscrits à des formations de sensibilisation suivant leurs domaines de travail ? | F23: 0
A24: [ ] | B24: A.7.2.3 | C24: Processus disciplinaire | D24: 1. Existe-t-il un processus disciplinaire formel qui permet à l'organisation de prendre des mesures contre les employés qui ont commis une violation de la sécurité de l'information? 2. Celles-ci sont elles communiqués aux parties intéressés ? | F24: 0
B25: A.7.3 | C25: Rupture, terme ou modification du contrat de travail
A26: [ ] | B26: A.7.3.1 | C26: Achèvement ou modification des responsabilités associées au contrat de travail | D26: 1. Existe-t-il une procédure documentée pour mettre fin ou modifier des fonctions professionnelles d’un employé? 2. Y a-t-il des fonctions dans la sécurité de l’information pouvant ne pas survivre si un employé est en rupture de contrat ? 3. L'organisation est-elle en mesure de faire respecter les obligations d’un employé en sécurité de l’information avant son départ ? | F26: 0
B27: A.8 | C27: Gestion des actifs
B28: A.8.1 | C28: Responsabilités relatives aux actifs
A29: [ ] | B29: A.8.1.1 | C29: Inventaire des actifs | D29: 1. Existe-t-il un inventaire de tous les actifs associés à l’information et moyens de traitement de l’information ? 2. Cet inventaire est-il mise à jour ? | F29: 0
A30: [ ] | B30: A.8.1.2 | C30: Propriété des actifs | D30: Tous les biens informationnels ont-il un propriétaire clairement défini qui est conscient de ses responsabilités ? | F30: 0
A31: [ ] | B31: A.8.1.3 | C31: Utilisation correcte des actifs | D31: 1. Existe-t-il une politique d'utilisation pour chaque classe / type d'actif d'information? 2. Les utilisateurs sont-ils au courant de cette politique avant utilisation? | F31: 0
A32: [ ] | B32: A.8.1.4 | C32: Restitution des actifs | D32: Y a-t-il un processus en place pour que les employés en fin de contrat retournent les actifs en leur possession ? | F32: 0
B33: A.8.2 | C33: Classification de l’information
A34: [ ] | B34: A.8.2.1 | C34: Classification des informations | D34: 1. Existe-t-il une politique régissant la classification de l'information? 2. Existe-t-il un processus par lequel toutes les informations peuvent être classées de manière appropriée? | F34: 0
A35: [ ] | B35: A.8.2.2 | C35: Marquage des informations | D35: Existe-t-il un processus ou une procédure pour s'assurer que la classification de l'information est correctement marquée sur chaque actif? | F35: 0
A36: [ ] | B36: A.8.2.3 | C36: Manipulation des actifs | D36: 1. Existe-t-il une procédure pour traiter chaque classification d'information? 2. Les utilisateurs d'actifs informationnels ont-ils été informés de cette procédure? | F36: 0
B37: A.8.3 | C37: Manipulation des supports
A38: [ ] | B38: A.8.3.1 | C38: Gestion des supports amovibles | D38: 1. Existe-t-il une politique régissant les supports amovibles? 2. Existe-t-il un processus couvrant « comment les supports amovibles sont gérés »? 3. La politique et les processus (s) sont-ils communiqués à tous les employés utilisant des supports amovibles? | F38: 0
A39: [ ] | B39: A.8.3.2 | C39: Mise en rebut des supports | D39: Existe-t-il une procédure formelle régissant la façon dont les supports amovibles sont détruits ? | F39: 0
A40: [ ] | B40: A.8.3.3 | C40: Manipulation des actifs | D40: 1. Existe-t-il une politique et un processus documentés détaillant la façon dont les médias physiques devraient être transportés? 2. Les médias sont ils protégés contre les accès non autorisés, les abus, la corruption? | F40: 0
...

Sheet Data
A1: Status
A2: 0
A3: 0.05
A4: 0.1
A5: 0.15
A6: 0.2
A7: 0.25
A8: 0.3
A9: 0.35
A10: 0.4
A11: 0.45
A12: 0.5
A13: 0.55
... A22: 1
